Workbook

Sheet Escala de cultos
A1: DATA | B1: Dia da semana | C1: Hora de início | D1: Hora de término | E1: Evento | F1: Event ID | G1: DIRIGENTE | H1: PREGADOR | I1: LEITURA | J1: Data especial? | K1: Última Atualização | L1: Escala sincronizada: 14/04/2026, 08:56:43 - 212 linhas processadas
A2: 46026 | B2: =IF(A2="","",CHOOSE(WEEKDAY(A2), "Domingo", "Segunda-feira", "Terça-feira", "Quarta-feira", "Quinta-feira", "Sexta-feira", "Sábado")) -> Domingo | C2: 0.70833333 | D2: 0.79166667 | E2: Culto Solene | F2: 745c83dhr16636rs1l0qbl57d0@google.com | G2: Diac. Aparecido Regino | H2: Pr. Augusto Lopes | I2: Marcos 1 | K2: 46126.372
A3: 46028 | B3: =IF(A3="","",CHOOSE(WEEKDAY(A3), "Domingo", "Segunda-feira", "Terça-feira", "Quarta-feira", "Quinta-feira", "Sexta-feira", "Sábado")) -> Terça-feira | C3: 0.8125 | D3: 0.875 | E3: Culto de Oração | F3: 0mc4cqfvv7cse610trk9qesvcs@google.com | K3: 46126.372
A4: 46030 | B4: =IF(A4="","",CHOOSE(WEEKDAY(A4), "Domingo", "Segunda-feira", "Terça-feira", "Quarta-feira", "Quinta-feira", "Sexta-feira", "Sábado")) -> Quinta-feira | C4: 0.8125 | D4: 0.875 | E4: Culto de oração | F4: mug7bo4i5htfjqo1gv193tpaco@google.com | K4: 46126.372
A5: 46033 | B5: =IF(A5="","",CHOOSE(WEEKDAY(A5), "Domingo", "Segunda-feira", "Terça-feira", "Quarta-feira", "Quinta-feira", "Sexta-feira", "Sábado")) -> Domingo | C5: 0.70833333 | D5: 0.79166667 | E5: Culto Solene | F5: 36o84dbdrh4gvdlcof9o2v89s8@google.com | G5: Ir. Gilmar Fonseca | H5: Pb. George Alves | I5: Marcos 2 | K5: 46126.372
A6: 46035 | B6: =IF(A6="","",CHOOSE(WEEKDAY(A6), "Domingo", "Segunda-feira", "Terça-feira", "Quarta-feira", "Quinta-feira", "Sexta-feira", "Sábado")) -> Terça-feira | C6: 0.8125 | D6: 0.875 | E6: Culto de oração | F6: ufep8squ17guti3e037t9ljhdc@google.com | K6: 46126.372
A7: 46037 | B7: =IF(A7="","",CHOOSE(WEEKDAY(A7), "Domingo", "Segunda-feira", "Terça-feira", "Quarta-feira", "Quinta-feira", "Sexta-feira", "Sábado")) -> Quinta-feira | C7: 0.8125 | D7: 0.875 | E7: Culto de oração | F7: 2k6ntnk9ulpkvu7oomnddq4slk@google.com | K7: 46126.372
A8: 46040 | B8: =IF(A8="","",CHOOSE(WEEKDAY(A8), "Domingo", "Segunda-feira", "Terça-feira", "Quarta-feira", "Quinta-feira", "Sexta-feira", "Sábado")) -> Domingo | C8: 0.70833333 | D8: 0.79166667 | E8: Culto Solene | F8: ng28ktrqujld0mf7c81j43c9lo@google.com | G8: Diac. Graça Lira | H8: Pr. Augusto Lopes | I8: Marcos 3 | K8: 46126.372
A9: 46042 | B9: =IF(A9="","",CHOOSE(WEEKDAY(A9), "Domingo", "Segunda-feira", "Terça-feira", "Quarta-feira", "Quinta-feira", "Sexta-feira", "Sábado")) -> Terça-feira | C9: 0.8125 | D9: 0.875 | E9: Culto de oração | F9: f196uj39qan893e5eq08b30enc@google.com | K9: 46126.372
A10: 46044 | B10: =IF(A10="","",CHOOSE(WEEKDAY(A10), "Domingo", "Segunda-feira", "Terça-feira", "Quarta-feira", "Quinta-feira", "Sexta-feira", "Sábado")) -> Quinta-feira | C10: 0.8125 | D10: 0.875 | E10: Culto de oração | F10: 23ucd8q40gu03koodt2jeco6to@google.com | K10: 46126.372
A11: 46047 | B11: =IF(A11="","",CHOOSE(WEEKDAY(A11), "Domingo", "Segunda-feira", "Terça-feira", "Quarta-feira", "Quinta-feira", "Sexta-feira", "Sábado")) -> Domingo | C11: 0.70833333 | D11: 0.79166667 | E11: Culto Solene | F11: kad2lr3342ng0h81qlgqdmiud8@google.com | G11: Diac. Juliana Goberto | H11: Semin. Ruth Alves | I11: Marcos 4 | K11: 46126.372
A12: 46047 | B12: =IF(A12="","",CHOOSE(WEEKDAY(A12), "Domingo", "Segunda-feira", "Terça-feira", "Quarta-feira", "Quinta-feira", "Sexta-feira", "Sábado")) -> Domingo | C12: 0.39583333 | D12: 0.45833333 | E12: Escola Bíblica | F12: mmr2vcic83l35b0b08lfl4d75k@google.com | H12: Pr. Augusto Lopes | K12: 46126.372
A13: 46049 | B13: =IF(A13="","",CHOOSE(WEEKDAY(A13), "Domingo", "Segunda-feira", "Terça-feira", "Quarta-feira", "Quinta-feira", "Sexta-feira", "Sábado")) -> Terça-feira | C13: 0.8125 | D13: 0.875 | E13: Culto de oração | F13: 1antt8fc5bu5torkdj268u4vsc@google.com | K13: 46126.372
A14: 46051 | B14: =IF(A14="","",CHOOSE(WEEKDAY(A14), "Domingo", "Segunda-feira", "Terça-feira", "Quarta-feira", "Quinta-feira", "Sexta-feira", "Sábado")) -> Quinta-feira | C14: 0.8125 | D14: 0.875 | E14: Culto de Doutrina | F14: 7e90f0jer3259pt4baa2bv2cpo@google.com | K14: 46126.372
A15: 46054 | B15: =IF(A15="","",CHOOSE(WEEKDAY(A15), "Domingo", "Segunda-feira", "Terça-feira", "Quarta-feira", "Quinta-feira", "Sexta-feira", "Sábado")) -> Domingo | C15: 0.70833333 | D15: 0.79166667 | E15: Culto Solene | F15: puqbuld8hbs73kvgfqfdgm3534@google.com | G15: Diac. Salete de Kássia | H15: Pr. Augusto Lopes | I15: Marcos 5 | K15: 46126.372
A16: 46054 | B16: =IF(A16="","",CHOOSE(WEEKDAY(A16), "Domingo", "Segunda-feira", "Terça-feira", "Quarta-feira", "Quinta-feira", "Sexta-feira", "Sábado")) -> Domingo | C16: 0.39583333 | D16: 0.45833333 | E16: Escola Bíblica | F16: 5s79eur648vc6g2hvt4a2j9us4@google.com | H16: Pr. Augusto Lopes | K16: 46126.372
A17: 46056 | B17: =IF(A17="","",CHOOSE(WEEKDAY(A17), "Domingo", "Segunda-feira", "Terça-feira", "Quarta-feira", "Quinta-feira", "Sexta-feira", "Sábado")) -> Terça-feira | C17: 0.8125 | D17: 0.85416667 | E17: Culto de Oração | F17: 8br1tpu0qaamj6conpv45cueec@google.com | K17: 46126.372
A18: 46058 | B18: =IF(A18="","",CHOOSE(WEEKDAY(A18), "Domingo", "Segunda-feira", "Terça-feira", "Quarta-feira", "Quinta-feira", "Sexta-feira", "Sábado")) -> Quinta-feira | C18: 0.8125 | D18: 0.875 | E18: Culto de Doutrina | F18: 814969bsu2n9naf0vhv78lnb3k@google.com | G18: Pr. Augusto Lopes | K18: 46126.372
A19: 46061 | B19: =IF(A19="","",CHOOSE(WEEKDAY(A19), "Domingo", "Segunda-feira", "Terça-feira", "Quarta-feira", "Quinta-feira", "Sexta-feira", "Sábado")) -> Domingo | C19: 0.70833333 | D19: 0.79166667 | E19: Culto Solene | F19: f718ukji2verfo8ji49bc2eldo@google.com | G19: Ir. Lisiane Flavia Lopes | H19: Pb. George Alves | I19: Marcos 6 | K19: 46126.372
A20: 46061 | B20: =IF(A20="","",CHOOSE(WEEKDAY(A20), "Domingo", "Segunda-feira", "Terça-feira", "Quarta-feira", "Quinta-feira", "Sexta-feira", "Sábado")) -> Domingo | C20: 0.39583333 | D20: 0.45833333 | E20: Escola Bíblica | F20: l7tet8dj3fn59u9bghgrslg5kk@google.com | H20: Pr. Augusto Lopes | K20: 46126.372
A21: 46063 | B21: =IF(A21="","",CHOOSE(WEEKDAY(A21), "Domingo", "Segunda-feira", "Terça-feira", "Quarta-feira", "Quinta-feira", "Sexta-feira", "Sábado")) -> Terça-feira | C21: 0.8125 | D21: 0.875 | E21: Culto na praça | F21: gjchkth4knokrmuin9j2cikuuo@google.com | G21: Pr. Augusto Lopes | K21: 46126.372
A22: 46065 | B22: =IF(A22="","",CHOOSE(WEEKDAY(A22), "Domingo", "Segunda-feira", "Terça-feira", "Quarta-feira", "Quinta-feira", "Sexta-feira", "Sábado")) -> Quinta-feira | C22: 0.8125 | D22: 0.875 | E22: Culto de Doutrina | F22: jm1769tv7e8hb5q6sd1l62888s@google.com | G22: Pr. Augusto Lopes | K22: 46126.372
A23: 46068 | B23: =IF(A23="","",CHOOSE(WEEKDAY(A23), "Domingo", "Segunda-feira", "Terça-feira", "Quarta-feira", "Quinta-feira", "Sexta-feira", "Sábado")) -> Domingo | C23: 0.70833333 | D23: 0.79166667 | E23: Culto Solene | F23: 1nachb7ee9j2pdrhhh629rkrts@google.com | G23: Diac. Simone Oliveira | H23: Semin. Gediael Kallebe | I23: Marcos 7 | J23: CARNAVAL | K23: 46126.372
A24: 46068 | B24: =IF(A24="","",CHOOSE(WEEKDAY(A24), "Domingo", "Segunda-feira", "Terça-feira", "Quarta-feira", "Quinta-feira", "Sexta-feira", "Sábado")) -> Domingo | C24: 0.39583333 | D24: 0.45833333 | E24: Escola Bíblica (SUSPENSA) | F24: npdhnl05b9i4iqduuf2augpd50@google.com | J24: CARNAVAL | K24: 46126.372
A25: 46070 | B25: =IF(A25="","",CHOOSE(WEEKDAY(A25), "Domingo", "Segunda-feira", "Terça-feira", "Quarta-feira", "Quinta-feira", "Sexta-feira", "Sábado")) -> Terça-feira | C25: 0.8125 | D25: 0.875 | E25: Culto de Oração (SUSPENSO) | F25: 9nmkfl7j4dpmnhte9fcman0e7o@google.com | K25: 46126.372
A26: 46072 | B26: =IF(A26="","",CHOOSE(WEEKDAY(A26), "Domingo", "Segunda-feira", "Terça-feira", "Quarta-feira", "Quinta-feira", "Sexta-feira", "Sábado")) -> Quinta-feira | C26: 0.8125 | D26: 0.875 | E26: Culto de Doutrina | F26: i5k13o7qqcd2lhv1opjtsl3bgs@google.com | K26: 46126.372
A27: 46075 | B27: =IF(A27="","",CHOOSE(WEEKDAY(A27), "Domingo", "Segunda-feira", "Terça-feira", "Quarta-feira", "Quinta-feira", "Sexta-feira", "Sábado")) -> Domingo | C27: 0.70833333 | D27: 0.79166667 | E27: Culto Solene | F27: llnkr6sh3b7rac3ir7o8cbmafk@google.com | G27: Diac. Adeildo Natalício | H27: Semin. Ruth Alves | K27: 46126.372
A28: 46075 | B28: =IF(A28="","",CHOOSE(WEEKDAY(A28), "Domingo", "Segunda-feira", "Terça-feira", "Quarta-feira", "Quinta-feira", "Sexta-feira", "Sábado")) -> Domingo | C28: 0.39583333 | D28: 0.45833333 | E28: Escola Bíblica | F28: 5q1m05rdsrcu9ptfl3jq544hsc@google.com | G28: Pr. Augusto Lopes | K28: 46126.372
A29: 46077 | B29: =IF(A29="","",CHOOSE(WEEKDAY(A29), "Domingo", "Segunda-feira", "Terça-feira", "Quarta-feira", "Quinta-feira", "Sexta-feira", "Sábado")) -> Terça-feira | C29: 0.8125 | D29: 0.875 | E29: Culto na praça | F29: japolbm16a7191lhocad4s59m8@google.com | G29: Pr. Augusto Lopes | K29: 46126.372
A30: 46079 | B30: =IF(A30="","",CHOOSE(WEEKDAY(A30), "Domingo", "Segunda-feira", "Terça-feira", "Quarta-feira", "Quinta-feira", "Sexta-feira", "Sábado")) -> Quinta-feira | C30: 0.8125 | D30: 0.875 | E30: Culto de Doutrina | F30: 7ji4qgnq0072pngun6sk3r5sv0@google.com | G30: Pr. Augusto Lopes | K30: 46126.372
A31: 46082 | B31: =IF(A31="","",CHOOSE(WEEKDAY(A31), "Domingo", "Segunda-feira", "Terça-feira", "Quarta-feira", "Quinta-feira", "Sexta-feira", "Sábado")) -> Domingo | C31: 0.70833333 | D31: 0.79166667 | E31: Culto Solene | F31: 0eq4ic9ea60gpnoujpbg6ova10@google.com | G31: Ir. Ana Amélia | H31: Pr. Augusto Lopes | I31: Marcos 9 | K31: 46126.372
A32: 46082 | B32: =IF(A32="","",CHOOSE(WEEKDAY(A32), "Domingo", "Segunda-feira", "Terça-feira", "Quarta-feira", "Quinta-feira", "Sexta-feira", "Sábado")) -> Domingo | C32: 0.39583333 | D32: 0.45833333 | E32: Escola Bíblica | F32: dt80tsfkg53q5so4umviocrtbo@google.com | G32: Pr. Augusto Lopes | K32: 46126.372
A33: 46084 | B33: =IF(A33="","",CHOOSE(WEEKDAY(A33), "Domingo", "Segunda-feira", "Terça-feira", "Quarta-feira", "Quinta-feira", "Sexta-feira", "Sábado")) -> Terça-feira | C33: 0.8125 | D33: 0.875 | E33: Culto de Oração | F33: p1dp8a9m2f2gpeq0q2r5lnd6ac@google.com | K33: 46126.372
A34: 46086 | B34: =IF(A34="","",CHOOSE(WEEKDAY(A34), "Domingo", "Segunda-feira", "Terça-feira", "Quarta-feira", "Quinta-feira", "Sexta-feira", "Sábado")) -> Quinta-feira | C34: 0.8125 | D34: 0.875 | E34: Culto de Doutrina | F34: vap9e3be54d02dv3cegkhj6u10@google.com | G34: Pr. Augusto Lopes | K34: 46126.372
A35: 46089 | B35: =IF(A35="","",CHOOSE(WEEKDAY(A35), "Domingo", "Segunda-feira", "Terça-feira", "Quarta-feira", "Quinta-feira", "Sexta-feira", "Sábado")) -> Domingo | C35: 0.70833333 | D35: 0.79166667 | E35: Culto Solene | F35: ie00p9kbqoom992bkm52usdm4s@google.com | G35: Ir. Ana Dupont | H35: Pb. George Alves | I35: Marcos 10 | J35: Dia Internacional da Mulher | K35: 46126.372
A36: 46089 | B36: =IF(A36="","",CHOOSE(WEEKDAY(A36), "Domingo", "Segunda-feira", "Terça-feira", "Quarta-feira", "Quinta-feira", "Sexta-feira", "Sábado")) -> Domingo | C36: 0.39583333 | D36: 0.45833333 | E36: Escola Bíblica | F36: 9k89ri66m111dn42v0u7at78io@google.com | G36: Pr. Augusto Lopes | K36: 46126.372
A37: 46091 | B37: =IF(A37="","",CHOOSE(WEEKDAY(A37), "Domingo", "Segunda-feira", "Terça-feira", "Quarta-feira", "Quinta-feira", "Sexta-feira", "Sábado")) -> Terça-feira | C37: 0.8125 | D37: 0.875 | E37: Culto na praça | F37: 701oq76l80am0pd2kdq4ptnjqc@google.com | G37: Pr. Augusto Lopes | K37: 46126.372
A38: 46093 | B38: =IF(A38="","",CHOOSE(WEEKDAY(A38), "Domingo", "Segunda-feira", "Terça-feira", "Quarta-feira", "Quinta-feira", "Sexta-feira", "Sábado")) -> Quinta-feira | C38: 0.8125 | D38: 0.875 | E38: Culto de Doutrina | F38: 8gbr457dl6132hg7muqibrmd4c@google.com | G38: Pr. Augusto Lopes | K38: 46126.372
A39: 46096 | B39: =IF(A39="","",CHOOSE(WEEKDAY(A39), "Domingo", "Segunda-feira", "Terça-feira", "Quarta-feira", "Quinta-feira", "Sexta-feira", "Sábado")) -> Domingo | C39: 0.70833333 | D39: 0.79166667 | E39: Culto Solene | F39: p1q9dbp52d8f44cssea1n3rnd0@google.com | G39: Diac. Aparecido Regino | H39: Pr. Augusto Lopes | I39: Marcos 11 | K39: 46126.372
A40: 46096 | B40: =IF(A40="","",CHOOSE(WEEKDAY(A40), "Domingo", "Segunda-feira", "Terça-feira", "Quarta-feira", "Quinta-feira", "Sexta-feira", "Sábado")) -> Domingo | C40: 0.39583333 | D40: 0.45833333 | E40: Escola Bíblica | F40: 5u0dt3i3asrf1oe1oitveumsf8@google.com | G40: Pr. Augusto Lopes | K40: 46126.372
...

Sheet Frequência
A1: DIRIGENTES CULTO DE DOMINGO
A2: Diac. Adeildo Natalício | B2: Ir. Ana Amélia | C2: Ir. Ana Dupont | D2: Diac. Aparecido Regino | E2: Ir. Gilmar Fonseca | F2: Ir. Naim | G2: Ir. Fabiana | H2: Ir. Dilma Martins | I2: Diac. Luciano
A3: =COUNTIF('Escala de cultos'!$G$2:$G$2010,A2) -> 7 | B3: =COUNTIF('Escala de cultos'!$G$2:$G$2010,B2) -> 7 | C3: =COUNTIF('Escala de cultos'!$G$2:$G$2010,C2) -> 5 | D3: =COUNTIF('Escala de cultos'!$G$2:$G$2010,D2) -> 5 | E3: =COUNTIF('Escala de cultos'!$G$2:$G$2010,E2) -> 7 | F3: =COUNTIF('Escala de cultos'!$G$2:$G$2010,F2) -> 2 | G3: =COUNTIF('Escala de cultos'!$G$2:$G$2010,G2) -> 2 | H3: =COUNTIF('Escala de cultos'!$G$2:$G$2010,H2) -> 3 | I3: =COUNTIF('Escala de cultos'!$G$2:$G$2010,I2) -> 2
A4: Diac. Graça Lira | B4: Diac. Juliana Goberto | C4: Diac. Salete de Kássia | D4: Ir. Lisiane Flavia Lopes | E4: Diac. Simone Oliveira | F4: Semin. Gediael Kallebe | H4: Ir. Edjane
A5: =COUNTIF('Escala de cultos'!$G$2:$G$2010,A4) -> 7 | B5: =COUNTIF('Escala de cultos'!$G$2:$G$2010,B4) -> 7 | C5: =COUNTIF('Escala de cultos'!$G$2:$G$2010,C4) -> 7 | D5: =COUNTIF('Escala de cultos'!$G$2:$G$2010,D4) -> 8 | E5: =COUNTIF('Escala de cultos'!$G$2:$G$2010,E4) -> 7 | F5: =COUNTIF('Escala de cultos'!$G$2:$G$2010,F4) -> 2 | G5: =COUNTIF('Escala de cultos'!$G$2:$G$2010,G4) -> 0 | H5: =COUNTIF('Escala de cultos'!$G$2:$G$2010,H4) -> 2
A6: PREGADORES
A7: Pr. Augusto Lopes | B7: Pb. George Alves | C7: Semin. Ruth Alves | D7: Semin. Gediael Kallebe | E7: Diac. Adeildo Natalício | F7: Convidado | G7: Ir. Ana Claudia | H7: Diac. Adeildo Natalício | I7: Diac. Aparecido Regino
A8: =COUNTIF('Escala de cultos'!$H$2:$H$2010,A7) -> 32 | B8: =COUNTIF('Escala de cultos'!$H$2:$H$2010,B7) -> 22 | C8: =COUNTIF('Escala de cultos'!$H$2:$H$2010,C7) -> 11 | D8: =COUNTIF('Escala de cultos'!$H$2:$H$2010,D7) -> 12 | E8: =COUNTIF('Escala de cultos'!$H$2:$H$2010,E7) -> 5 | F8: =COUNTIF('Escala de cultos'!$H$2:$H$2010,F7) -> 1 | G8: =COUNTIF('Escala de cultos'!$H$2:$H$2010,G7) -> 5 | H8: =COUNTIF('Escala de cultos'!$H$2:$H$2010,H7) -> 5 | I8: =COUNTIF('Escala de cultos'!$H$2:$H$2010,I7) -> 5

Sheet Calendário Diretoria e Oficiais
A1: DATA | B1: Hora de início | C1: Hora de término | D1: Evento | E1: Event ID | F1: PAUTA | G1: Diretoria sincronizada: 27/01/2026, 16:34:20 - 1 linhas | H1: Diretoria sincronizada: 27/01/2026, 16:38:51 - 1 linhas | I1: Diretoria sincronizada: 27/01/2026, 16:43:02 - 4 linhas
A2: 46108 | B2: 0.8125 | C2: 0.875 | D2: Reunião - Diretoria e Oficiais | E2: ba0i059g37gi9tusrh80v4uqlk@google.com | F2: 1. Apresentação do relatório financeiro 2. Batismo de novos membros 3. Aniversário da Igreja 4. Análise da reforma do templo
A3: 46178 | B3: 0.8125 | C3: 0.875 | D3: Reunião - Diretoria e Oficiais | E3: ln6iecv264tek37imf52rv298g@google.com | F3: 1. Apresentação de relatório financeiro
A4: 46276 | B4: 0.8125 | C4: 0.875 | D4: Reunião - Diretoria e Oficiais | E4: 11tnlrmeufthjuujf7r3k5bma8@google.com | F4: 1. Apresentação de relatório financeiro
A5: 46360 | B5: 0.8125 | C5: 0.875 | D5: Reunião - Diretoria e Oficiais | E5: p88t06sh3gu857q5n718t1inrk@google.com | F5: 1. Apresentação de relatório financeiro
